Workbook

Sheet sector_no
A1: 1 | B1: Agriculture, Fishing, Quarrying, Utilities and Sewerage & Waste Management
A2: 2 | B2: Manufacturing
A3: 3 | B3: Construction
A4: 4 | B4: Wholesale & Retail Trade
A5: 5 | B5: Transportation & Storage
A6: 6 | B6: Accommodation & Food Services
A7: 7 | B7: Information & Communications
A8: 8 | B8: Financial & Insurance Services
A9: 9 | B9: Real Estate Services
A10: 10 | B10: Professional Services
A11: 11 | B11: Administrative & Support Services
A12: 12 | B12: Public Administration & Education
... A15: 15 | B15: Other Community, Social & Personal Services

Sheet sector_mapping
A1: Unemployment data from MOM website (15) | B1: Singapore IOT (broad sector) (20) | C1: ADB dataset (35)
A2: Agriculture, Fishing, Quarrying, Utilities and Sewerage & Waste Management | B2: Other Goods Industries | C2: Agriculture, hunting, forestry, and fishing; Mining and quarrying; Electricity, gas, and water supply; Other nonmetallic minerals
A3: Manufacturing | B3: Manufacturing, Utilities | C3: Manufacturing, nec; recycling; Food, beverages, and tobacco; Textiles and textile products; Leather, leather products, and footwear; Wood and products of wood and cork; Pulp, paper, paper products, printing, publishing; Coke, petroleum, nuclear fuel; Chemicals and chemical products; Rubber and plastics; Basic metals, fabricated metal; Machinery, nec; Electrical, optical equipment; Transport equipment
A4: Construction | B4: Construction | C4: Construction
A5: Wholesale & Retail Trade | B5: Wholesale Trade,Retail Trade | C5: Wholesale trade and commission trade, except motor vehicles and motorcycles; Retail trade except motor vehicles and motorcycles; repair of household goods; Sale, maintenance, repair of motor vehicles, motorcycles, retail sale of fuel
A6: Transportation & Storage | B6: Transportation & Storage | C6: Inland transport; Water transport; Air transport; Other supporting auxiliary transport activities, activities of travel agencies
A7: Accommodation & Food Services | B7: Accommodation,Food & Beverage Services | C7: Hotels and restaurants
A8: Information & Communications | B8: Information & Communications | C8: Post and telecommunications
A9: Financial & Insurance Services | B9: Finance & Insurance | C9: Financial intermediation
A10: Real Estate Services | B10: Real estate, Ownership of Dwellings | C10: Real estate activities
A11: Professional Services | B11: Professional Services | C11: Renting of M&E and other business activities
A12: Administrative & Support Services | B12: Administrative & Support Services | C12: Other supporting auxiliary transport activities; Activities of travel agencies; Other community, social, personal services
... A14: Health & Social Services | B14: Health & Social Services | C14: Health and social work
A15: Arts, Entertainment & Recreation | B15: Arts, Entertainment & Recreation
A16: Other Community, Social & Personal Services | B16: Other Services – Others | C16: Private households with employed persons; Other community, social and personal services

Sheet 2020 resident unemployment rate
A1: Agriculture, Fishing, Quarrying, Utilities and Sewerage & Waste Management | B1: 0.028002661
A2: Manufacturing | B2: 0.010164607
A3: Construction | B3: 0.035680099
A4: Wholesale & Retail Trade | B4: 0.011990496
A5: Transportation & Storage | B5: 0.013762022
A6: Accommodation & Food Services | B6: 0.034761072
A7: Information & Communications | B7: 0.014652728
A8: Financial & Insurance Services | B8: 0.0054227333
A9: Real Estate Services | B9: 0.012943357
A10: Professional Services | B10: 0.0093704619
A11: Administrative & Support Services | B11: 0.021126402
A12: Public Administration & Education | B12: 0.0069300513
... A15: Other Community, Social & Personal Services | B15: 0.029070709

Sheet lapi div sector output
A1: Agriculture, Fishing, Quarrying, Utilities and Sewerage & Waste Management | B1: 0.091518026
A2: Manufacturing | B2: 0.073984331
A3: Construction | B3: 0.1930951
A4: Wholesale & Retail Trade | B4: 0.13671499
A5: Transportation & Storage | B5: 0.080462306
A6: Accommodation & Food Services | B6: 0.24343913
A7: Information & Communications | B7: 0.13211656
A8: Financial & Insurance Services | B8: 0.20112269
A9: Real Estate Services | B9: 0.059095596
A10: Professional Services | B10: 0.32948689
A11: Administrative & Support Services | B11: 0.25206086
A12: Public Administration & Education | B12: 0.42623459
... A15: Other Community, Social & Personal Services | B15: 0.54414931

Sheet sector inoperability
A1: Sector ID | B1: Sector | C1: Initial inoperability
A2: 1 | B2: Agriculture, Fishing, Quarrying, Utilities and Sewerage & Waste Management | C2: ='lapi div sector output'!B1*'2020 resident unemployment rate'!B1 -> 0.0025627483
A3: 2 | B3: Manufacturing | C3: ='lapi div sector output'!B2*'2020 resident unemployment rate'!B2 -> 0.00075202168
A4: 3 | B4: Construction | C4: ='lapi div sector output'!B3*'2020 resident unemployment rate'!B3 -> 0.0068896521
A5: 4 | B5: Wholesale & Retail Trade | C5: ='lapi div sector output'!B4*'2020 resident unemployment rate'!B4 -> 0.0016392806
A6: 5 | B6: Transportation & Storage | C6: ='lapi div sector output'!B5*'2020 resident unemployment rate'!B5 -> 0.0011073241
A7: 6 | B7: Accommodation & Food Services | C7: ='lapi div sector output'!B6*'2020 resident unemployment rate'!B6 -> 0.0084622052
A8: 7 | B8: Information & Communications | C8: ='lapi div sector output'!B7*'2020 resident unemployment rate'!B7 -> 0.001935868
A9: 8 | B9: Financial & Insurance Services | C9: ='lapi div sector output'!B8*'2020 resident unemployment rate'!B8 -> 0.0010906347
A10: 9 | B10: Real Estate Services | C10: ='lapi div sector output'!B9*'2020 resident unemployment rate'!B9 -> 0.00076489538
A11: 10 | B11: Professional Services | C11: ='lapi div sector output'!B10*'2020 resident unemployment rate'!B10 -> 0.0030874444
A12: 11 | B12: Administrative & Support Services | C12: ='lapi div sector output'!B11*'2020 resident unemployment rate'!B11 -> 0.0053251391
A13: 12 | B13: Public Administration & Education | C13: ='lapi div sector output'!B12*'2020 resident unemployment rate'!B12 -> 0.0029538276
... A16: 15 | B16: Other Community, Social & Personal Services | C16: ='lapi div sector output'!B15*'2020 resident unemployment rate'!B15 -> 0.015818806

Sheet sector mapping
A1: Sector ID | B1: Aggregated Sectors | C1: Singapore IOT Sectors
A3: 1 | B3: Agriculture, Fishing, Quarrying, Utilities and Sewerage & Waste Management | C3: Other Goods Industries
A4: 2 | B4: Manufacturing | C4: Manufacturing, Utilities
A5: 3 | B5: Construction | C5: Construction
A6: 4 | B6: Wholesale & Retail Trade | C6: Wholesale Trade, Retail Trade
A7: 5 | B7: Transportation & Storage | C7: Transportation & Storage
A8: 6 | B8: Accommodation & Food Services | C8: Accommodation & Food & Beverage Services
A9: 7 | B9: Information & Communications | C9: Information & Communications
A10: 8 | B10: Financial & Insurance Services | C10: Financial & Insurance Services
A11: 9 | B11: Real Estate Services | C11: Real Estate, Ownership of Dwellings
A12: 10 | B12: Professional Services | C12: Professional, Scientific & Technical Services
A13: 11 | B13: Administrative & Support Services | C13: Administrative & Support Services
A14: 12 | B14: Public Administration & Education | C14: Public Administration & Defence, Education
... A17: 15 | B17: Other Community, Social & Personal Services | C17: Other Services – Others

Sheet c_star
A1: Sectors | B1: GDP change | C1: as planned c | D1: reduced c | E1: c_diff | F1: x | G1: c*
A2: Agriculture, Fishing, Quarrying, Utilities and Sewerage & Waste Management | B2: 0.024468016 | C2: 4100.8373 | D2: =C2*(1+B2) -> 4201.1767 | E2: =C2-D2 -> -100.33935 | F2: 18178.163 | G2: =E2/F2 -> -0.005519774
A3: Manufacturing | B3: -0.1057232 | C3: 257868.24 | D3: =C3*(1+B3) -> 230605.58 | E3: =C3-D3 -> 27262.656 | F3: 358100.86 | G3: =E3/F3 -> 0.076131222
A4: Construction | B4: -0.64822832 | C4: 34218.741 | D4: =C4*(1+B4) -> 12037.184 | E4: =C4-D4 -> 22181.557 | F4: 62463.208 | G4: =E4/F4 -> 0.35511396
A5: Wholesale & Retail Trade | B5: 0.014681563 | C5: 178435.42 | D5: =C5*(1+B5) -> 181055.13 | E5: =C5-D5 -> -2619.7109 | F5: 214668.59 | G5: =E5/F5 -> -0.012203513
A6: Transportation & Storage | B6: -0.10064195 | C6: 97650.934 | D6: =C6*(1+B6) -> 87823.154 | E6: =C6-D6 -> 9827.7803 | F6: 171885.82 | G6: =E6/F6 -> 0.057176215
A7: Accommodation & Food Services | B7: -0.39541051 | C7: 17603.875 | D7: =C7*(1+B7) -> 10643.118 | E7: =C7-D7 -> 6960.7571 | F7: 23161.395 | G7: =E7/F7 -> 0.30053272
A8: Information & Communications | B8: -0.0080595652 | C8: 68734.687 | D8: =C8*(1+B8) -> 68180.716 | E8: =C8-D8 -> 553.97169 | F8: 102294.49 | G8: =E8/F8 -> 0.00541546
A9: Financial & Insurance Services | B9: -0.083654302 | C9: 86157.011 | D9: =C9*(1+B9) -> 78949.606 | E9: =C9-D9 -> 7207.4046 | F9: 136763 | G9: =E9/F9 -> 0.052699958
A10: Real Estate Services | B10: -0.27212984 | C10: 34240.7 | D10: =C10*(1+B10) -> 24922.784 | E10: =C10-D10 -> 9317.9162 | F10: 54765.059 | G10: =E10/F10 -> 0.17014345
A11: Professional Services | B11: -0.13419438 | C11: 30143.961 | D11: =C11*(1+B11) -> 26098.811 | E11: =C11-D11 -> 4045.1501 | F11: 61620.38 | G11: =E11/F11 -> 0.065646302
A12: Administrative & Support Services | B12: -0.24623281 | C12: 8929.316 | D12: =C12*(1+B12) -> 6730.6254 | E12: =C12-D12 -> 2198.6906 | F12: 31876.146 | G12: =E12/F12 -> 0.068976048
A13: Public Administration & Education | B13: -0.28383092 | C13: 51219.46 | D13: =C13*(1+B13) -> 36681.794 | E13: =C13-D13 -> 14537.666 | F13: 57064.582 | G13: =E13/F13 -> 0.25475813
... A16: Other Community, Social & Personal Services | B16: -0.274567 | C16: 6986.8237 | D16: =C16*(1+B16) -> 5068.4725 | E16: =C16-D16 -> 1918.3512 | F16: 9609.5117 | G16: =E16/F16 -> 0.19963046

Sheet A
C1: 1 | D1: 2 | E1: 3 | F1: 4 | G1: 5 | H1: 6 | I1: 7 | J1: 8 | K1: 9 | L1: 10 | M1: 11 | N1: 12 | O1: 13 | P1: 14 | Q1: 15
C2: Agriculture, Fishing, Quarrying, Utilities and Sewerage & Waste Management | D2: Manufacturing | E2: Construction | F2: Wholesale & Retail Trade | G2: Transportation & Storage | H2: Accommodation & Food Services | I2: Information & Communications | J2: Financial & Insurance Services | K2: Real Estate Services | L2: Professional Services | M2: Administrative & Support Services | N2: Public Administration & Education | O2: Health & Social Services | P2: Arts, Entertainment & Recreation | Q2: Other Community, Social & Personal Services
A3: 1 | B3: Agriculture, Fishing, Quarrying, Utilities and Sewerage & Waste Management | C3: 0.23703323 | D3: 0.0083369867 | E3: 0.0031851406 | F3: 0.0039608692 | G3: 0.0033022905 | H3: 0.039216416 | I3: 0.0056449582 | J3: 0.0021996585 | K3: 0.013054769 | L3: 0.0040668444 | M3: 0.0021786479 | N3: 0.029730965 | O3: 0.011414016 | P3: 0.026220749 | Q3: 0.012775113
A4: 2 | B4: Manufacturing | C4: 0.027445875 | D4: 0.16692862 | E4: 0.079083231 | F4: 0.023051885 | G4: 0.06228342 | H4: 0.089176865 | I4: 0.055410144 | J4: 0.0063642972 | K4: 0.020920185 | L4: 0.063928759 | M4: 0.046738037 | N4: 0.036401169 | O4: 0.06228833 | P4: 0.028431722 | Q4: 0.039967379
A5: 3 | B5: Construction | C5: 0.009185411 | D5: 0.0013910955 | E5: 0.3775507 | F5: 0.00080783128 | G5: 0.0011572473 | H5: 0.00582825 | I5: 0.00073048512 | J5: 0.00085148612 | K5: 0.044740415 | L5: 0.0054590235 | M5: 0.00093373269 | N5: 0.0054002551 | O5: 0.0029441297 | P5: 0.0095219787 | Q5: 0.0010703562
A6: 4 | B6: Wholesale & Retail Trade | C6: 0.013335775 | D6: 0.033549145 | E6: 0.028265431 | F6: 0.031357347 | G6: 0.021724065 | H6: 0.054948534 | I6: 0.047453055 | J6: 0.011072326 | K6: 0.0099302385 | L6: 0.017204243 | M6: 0.018437025 | N6: 0.018236224 | O6: 0.024870948 | P6: 0.014821193 | Q6: 0.015603654
A7: 5 | B7: Transportation & Storage | C7: 0.0087515388 | D7: 0.0087432915 | E7: 0.0047596435 | F7: 0.10324923 | G7: 0.24589471 | H7: 0.0099719987 | I7: 0.01169882 | J7: 0.0077762602 | K7: 0.0087593131 | L7: 0.0090010886 | M7: 0.010920828 | N7: 0.036484602 | O7: 0.0053664588 | P7: 0.0066955004 | Q7: 0.0073820088
A8: 6 | B8: Accommodation & Food Services | C8: 0.0011454733 | D8: 0.00099798615 | E8: 0.00068808025 | F8: 0.0044660186 | G8: 0.0062864821 | H8: 0.010234237 | I8: 0.0078423827 | J8: 0.0059587255 | K8: 0.0026695507 | L8: 0.0065381145 | M8: 0.0067031566 | N8: 0.0045688076 | O8: 0.0031672631 | P8: 0.0085110667 | Q8: 0.0063815209
A9: 7 | B9: Information & Communications | C9: 0.0079552867 | D9: 0.0027550746 | E9: 0.0032204894 | F9: 0.012246955 | G9: 0.0066718495 | H9: 0.0085433023 | I9: 0.1552835 | J9: 0.038572592 | K9: 0.010917437 | L9: 0.046024565 | M9: 0.013861707 | N9: 0.03725085 | O9: 0.02916 | P9: 0.025879255 | Q9: 0.016707644
A10: 8 | B10: Financial & Insurance Services | C10: 0.015451886 | D10: 0.0084776943 | E10: 0.01167314 | F10: 0.034137086 | G10: 0.011187725 | H10: 0.01952948 | I10: 0.01297954 | J10: 0.17021553 | K10: 0.079697907 | L10: 0.024519375 | M10: 0.02279139 | N10: 0.085672522 | O10: 0.017582767 | P10: 0.02148428 | Q10: 0.014390273
A11: 9 | B11: Real Estate Services | C11: 0.0086795568 | D11: 0.0029409815 | E11: 0.0040238663 | F11: 0.027753387 | G11: 0.0088465939 | H11: 0.074563432 | I11: 0.0098098954 | J11: 0.019399615 | K11: 0.040731965 | L11: 0.018984588 | M11: 0.014399106 | N11: 0.018157238 | O11: 0.031586814 | P11: 0.023697117 | Q11: 0.035215359
A12: 10 | B12: Professional Services | C12: 0.016306879 | D12: 0.017419438 | E12: 0.021717977 | F12: 0.022616099 | G12: 0.011621262 | H12: 0.027797138 | I12: 0.031431761 | J12: 0.024594254 | K12: 0.061373241 | L12: 0.046676856 | M12: 0.014932094 | N12: 0.029821001 | O12: 0.020383752 | P12: 0.040715061 | Q12: 0.022708469
A13: 11 | B13: Administrative & Support Services | C13: 0.014632645 | D13: 0.0063115163 | E13: 0.012948823 | F13: 0.023006397 | G13: 0.016798468 | H13: 0.015100887 | I13: 0.019254083 | J13: 0.018184149 | K13: 0.036042647 | L13: 0.014096622 | M13: 0.061058388 | N13: 0.021557801 | O13: 0.022240275 | P13: 0.033004109 | Q13: 0.012220694
A14: 12 | B14: Public Administration & Education | C14: 0.0045189714 | D14: 0.0010000967 | E14: 0.0024749433 | F14: 0.004234702 | G14: 0.0033380544 | H14: 0.0072725369 | I14: 0.0040716486 | J14: 0.0039706411 | K14: 0.01204464 | L14: 0.0073005246 | M14: 0.0020982116 | N14: 0.021483541 | O14: 0.0037930255 | P14: 0.011072223 | Q14: 0.0040627975
... A17: 15 | B17: Other Community, Social & Personal Services | C17: 0.0016953968 | D17: 0.00036329123 | E17: 0.0015273999 | F17: 0.0012466873 | G17: 0.0023946234 | H17: 0.0034468347 | I17: 0.0021996181 | J17: 0.001844833 | K17: 0.0024075643 | L17: 0.0020673728 | M17: 0.0026723525 | N17: 0.0081337246 | O17: 0.004650061 | P17: 0.01402598 | Q17: 0.0077085707

Sheet 2019IOTable
C1: 1 | D1: 2 | E1: 3 | F1: 4 | G1: 5 | H1: 6 | I1: 7 | J1: 8 | K1: 9 | L1: 10 | M1: 11 | N1: 12 | O1: 13 | P1: 14 | Q1: 15 | R1: CT1 | S1: 21 | T1: 22 | U1: 23 | V1: 24 | W1: 25 | Y1: CT3
C2: Agriculture, Fishing, Quarrying, Utilities and Sewerage & Waste Management | D2: Manufacturing | E2: Construction | F2: Wholesale & Retail Trade | G2: Transportation & Storage | H2: Accommodation & Food Services | I2: Information & Communications | J2: Financial & Insurance Services | K2: Real Estate Services | L2: Professional Services | M2: Administrative & Support Services | N2: Public Administration & Education | O2: Health & Social Services | P2: Arts, Entertainment & Recreation | Q2: Other Community, Social & Personal Services | R2: Total intermediate use at basic prices | S2: Household and NPISHs final consumption expenditure | T2: Government final consumption expenditure | U2: Gross fixed capital formation | V2: Changes in inventories | W2: Exports of goods & services | X2: Total final output at basic prices | Y2: Total output at basic prices
A3: 1 | B3: Agriculture, Fishing, Quarrying, Utilities and Sewerage & Waste Management | C3: 4308.8287 | D3: 2985.4821 | E3: 198.9541 | F3: 850.2742 | G3: 567.6169 | H3: 908.3069 | I3: 577.4481 | J3: 300.8319 | K3: 714.9452 | L3: 250.6005 | M3: 69.4469 | N3: 1696.5851 | O3: 263.6289 | P3: 261.613 | Q3: 122.7626 | R3: 14077.325 | S3: 2089.3867 | T3: 436.7589 | U3: 112.3873 | V3: 20.3125 | W3: 1441.9919 | X3: 4100.8373 | Y3: 18178.163
A4: 2 | B4: Manufacturing | C4: 498.9156 | D4: 59777.284 | E4: 4939.7923 | F4: 4948.5157 | G4: 10705.636 | H4: 2065.4606 | I4: 5668.1522 | J4: 870.4004 | K4: 1145.6952 | L4: 3939.3144 | M4: 1489.8285 | N4: 2077.2175 | O4: 1438.6701 | P4: 283.6726 | Q4: 384.067 | R4: 100232.62 | S4: 4764.5359 | T4: 264.3985 | U4: 9283.9755 | V4: 1722.4049 | W4: 241832.92 | X4: 257868.24 | Y4: 358100.86
A5: 3 | B5: Construction | C5: 166.9739 | D5: 498.1525 | E5: 23583.028 | F5: 173.416 | G5: 198.9144 | H5: 134.9904 | I5: 74.7246 | J5: 116.4518 | K5: 2450.2115 | L5: 336.3871 | M5: 29.7638 | N5: 308.1633 | O5: 68.0004 | P5: 95.0039 | Q5: 10.2856 | R5: 28244.467 | S5: 31.907 | T5: 5.6617 | U5: 32445.845 | V5: 0 | W5: 1735.3274 | X5: 34218.741 | Y5: 62463.208
A6: 4 | B6: Wholesale & Retail Trade | C6: 242.4199 | D6: 12013.978 | E6: 1765.5495 | F6: 6731.4373 | G6: 3734.0586 | H6: 1272.6847 | I6: 4854.1859 | J6: 1514.2845 | K6: 543.8301 | L6: 1060.132 | M6: 587.7013 | N6: 1040.6425 | O6: 574.4429 | P6: 147.8759 | Q6: 149.9435 | R6: 36233.166 | S6: 15876.881 | T6: 94.0853 | U6: 5070.2534 | V6: 3.122 | W6: 157391.08 | X6: 178435.42 | Y6: 214668.59
A7: 5 | B7: Transportation & Storage | C7: 159.0869 | D7: 3130.9802 | E7: 297.3026 | F7: 22164.366 | G7: 42265.813 | H7: 230.9654 | I7: 1196.7248 | J7: 1063.5047 | K7: 479.7043 | L7: 554.6505 | M7: 348.1139 | N7: 2081.9786 | O7: 123.9488 | P7: 66.8032 | Q7: 70.9375 | R7: 74234.881 | S7: 8152.9352 | T7: 100.1712 | U7: 532.5968 | V7: 2.7954 | W7: 88862.436 | X7: 97650.934 | Y7: 171885.82
A8: 6 | B8: Accommodation & Food Services | C8: 20.8226 | D8: 357.3797 | E8: 42.9797 | F8: 958.7139 | G8: 1080.5571 | H8: 237.0392 | I8: 802.2325 | J8: 814.9332 | K8: 146.1981 | L8: 402.8811 | M8: 213.6708 | N8: 260.7171 | O8: 73.1541 | P8: 84.9177 | Q8: 61.3233 | R8: 5557.52 | S8: 9773.76 | T8: 8.2427 | U8: 119.4198 | V8: 0 | W8: 7702.4523 | X8: 17603.875 | Y8: 23161.395
A9: 7 | B9: Information & Communications | C9: 144.6125 | D9: 986.5946 | E9: 201.1621 | F9: 2629.0366 | G9: 1146.7963 | H9: 197.8748 | I9: 15884.646 | J9: 5275.3036 | K9: 597.8941 | L9: 2836.0512 | M9: 441.8578 | N9: 2125.7042 | O9: 673.5069 | P9: 258.2058 | Q9: 160.5523 | R9: 33559.798 | S9: 5351.8589 | T9: 98.2635 | U9: 5809.1774 | V9: 0.2992 | W9: 57475.088 | X9: 68734.687 | Y9: 102294.49
A10: 8 | B10: Financial & Insurance Services | C10: 280.8869 | D10: 3035.8696 | E10: 729.1418 | F10: 7328.16 | G10: 1923.0112 | H10: 452.33 | I10: 1327.7354 | J10: 23279.188 | K10: 4364.6606 | L10: 1510.8932 | M10: 726.5017 | N10: 4888.8667 | O10: 406.1082 | P10: 214.3557 | Q10: 138.2835 | R10: 50605.992 | S10: 20750.338 | T10: 429.3211 | U10: 597.4825 | V10: 0 | W10: 64379.87 | X10: 86157.011 | Y10: 136763
A11: 9 | B11: Real Estate Services | C11: 157.7784 | D11: 1053.168 | E11: 251.3436 | F11: 5957.7804 | G11: 1520.604 | H11: 1726.9931 | I11: 1003.4982 | J11: 2653.1496 | K11: 2230.6885 | L11: 1169.8375 | M11: 458.988 | N11: 1036.1352 | O11: 729.5589 | P11: 236.4339 | Q11: 338.4024 | R11: 20524.36 | S11: 24074.318 | T11: 141.0614 | U11: 7888.522 | V11: 0.0011 | W11: 2136.7976 | X11: 34240.7 | Y11: 54765.059
A12: 10 | B12: Professional Services | C12: 296.4291 | D12: 6237.9158 | E12: 1356.5745 | F12: 4854.9661 | G12: 1997.5301 | H12: 643.8205 | I12: 3215.2958 | J12: 3363.584 | K12: 3361.1092 | L12: 2876.2456 | M12: 475.9776 | N12: 1701.723 | O12: 470.8024 | P12: 406.2275 | Q12: 218.2173 | R12: 31476.418 | S12: 849.0924 | T12: 1331.1493 | U12: 7328.8946 | V12: 12.2659 | W12: 20622.559 | X12: 30143.961 | Y12: 61620.38
A13: 11 | B13: Administrative & Support Services | C13: 265.9946 | D13: 2260.1594 | E13: 808.825 | F13: 4938.7508 | G13: 2887.4184 | H13: 349.7576 | I13: 1969.5865 | J13: 2486.9188 | K13: 1973.8777 | L13: 868.6392 | M13: 1946.3061 | N13: 1230.1869 | O13: 513.6824 | P13: 329.2928 | Q13: 117.4349 | R13: 22946.831 | S13: 941.1703 | T13: 29.3055 | U13: 73.0604 | V13: 0.3416 | W13: 7885.4382 | X13: 8929.316 | Y13: 31876.146
A14: 12 | B14: Public Administration & Education | C14: 82.1466 | D14: 358.1355 | E14: 154.5929 | F14: 909.0575 | G14: 573.7642 | H14: 168.4421 | I14: 416.5072 | J14: 543.0368 | K14: 659.6254 | L14: 449.8611 | M14: 66.8829 | N14: 1225.9493 | O14: 87.6073 | P14: 110.4712 | Q14: 39.0415 | R14: 5845.1213 | S14: 6119.3827 | T14: 40697.753 | U14: 655.7852 | V14: 0.4193 | W14: 3746.12 | X14: 51219.46 | Y14: 57064.582
... A22: 25 | B22: Gross operating surplus | C22: 4090.4566 | D22: 72311.945 | E22: 3902.5947 | F22: 61536.341 | G22: 17168.762 | H22: 3893.1767 | I22: 8862.0758 | J22: 40550.357 | K22: 29326.855 | L22: 8988.0388 | M22: 13441.317 | N22: 3330.319 | O22: 2308.7598 | P22: 3522.3706 | Q22: 974.8712 | R22: 274208.24 | S22: 0 | T22: 0 | U22: 0 | V22: 0 | W22: 0 | X22: 0 | Y22: 274208.24
A23: RT4 | B23: Total inputs at basic prices | C23: 18178.163 | D23: 358100.86 | E23: 62463.208 | F23: 214668.59 | G23: 171885.82 | H23: 23161.395 | I23: 102294.49 | J23: 136763 | K23: 54765.059 | L23: 61620.38 | M23: 31876.146 | N23: 57064.582 | O23: 23096.945 | P23: 9977.3275 | Q23: 9609.5117 | R23: 1335525.5 | S23: 182886.72 | T23: 52648.889 | U23: 118467.68 | V23: 9073.323 | W23: 910314.14 | X23: 1273390.8 | Y23: 2608916.2
F32: Agriculture, Fishing, Quarrying, Utilities and Sewerage & Waste Management | G32: Manufacturing | H32: Construction | I32: Wholesale & Retail Trade | J32: Transportation & Storage | K32: Accommodation & Food Services | L32: Information & Communications
E33: Agriculture, Fishing, Quarrying, Utilities and Sewerage & Waste Management | F33: 4308.8287 | G33: 2985.4821 | H33: 198.9541 | I33: 850.2742 | J33: 567.6169 | K33: 908.3069 | L33: 577.4481
E34: Manufacturing | F34: 498.9156 | G34: 59777.284 | H34: 4939.7923 | I34: 4948.5157 | J34: 10705.636 | K34: 2065.4606 | L34: 5668.1522
E35: Construction | F35: 166.9739 | G35: 498.1525 | H35: 23583.028 | I35: 173.416 | J35: 198.9144 | K35: 134.9904 | L35: 74.7246
E36: Wholesale & Retail Trade | F36: 242.4199 | G36: 12013.978 | H36: 1765.5495 | I36: 6731.4373 | J36: 3734.0586 | K36: 1272.6847 | L36: 4854.1859
E37: Transportation & Storage | F37: 159.0869 | G37: 3130.9802 | H37: 297.3026 | I37: 22164.366 | J37: 42265.813 | K37: 230.9654 | L37: 1196.7248
E38: Accommodation & Food Services | F38: 20.8226 | G38: 357.3797 | H38: 42.9797 | I38: 958.7139 | J38: 1080.5571 | K38: 237.0392 | L38: 802.2325
E39: Information & Communications | F39: 144.6125 | G39: 986.5946 | H39: 201.1621 | I39: 2629.0366 | J39: 1146.7963 | K39: 197.8748 | L39: 15884.646
E40: Financial & Insurance Services | F40: 280.8869 | G40: 3035.8696 | H40: 729.1418 | I40: 7328.16 | J40: 1923.0112 | K40: 452.33 | L40: 1327.7354

Sheet updated 2019 IO table
D1: 1 | E1: 3 | F1: 2 | G1: 4 | H1: 5 | I1: 6 | J1: 7 | K1: 8 | L1: 9 | M1: 10 | N1: 11 | O1: 12 | P1: 13 | Q1: 14 | R1: 15 | S1: 16 | T1: 17 | U1: 18 | V1: 19 | W1: 20 | X1: CT1 | Z1: 21 | AA1: 22 | AB1: 23 | AC1: 24 | AD1: 25 | AE1: CT2 | AF1: CT3
D2: Agriculture, Fishing, Quarrying, Utilities and Sewerage & Waste Management | E2: Agriculture, Fishing, Quarrying, Utilities and Sewerage & Waste Management | F2: Manufacturing | G2: Construction | H2: Wholesale & Retail Trade | I2: Wholesale & Retail Trade | J2: Transportation & Storage | K2: Accommodation & Food Services | L2: Accommodation & Food Services | M2: Information & Communications | N2: Financial & Insurance Services | O2: Real Estate Services | P2: Real Estate Services | Q2: Professional Services | R2: Administrative & Support Services | S2: Public Administration & Education | T2: Public Administration & Education | U2: Health & Social Services | V2: Arts, Entertainment & Recreation | W2: Other Community, Social & Personal Services
D3: Other Goods Industries | E3: Utilities | F3: Manufacturing | G3: Construction | H3: Wholesale Trade | I3: Retail Trade | J3: Transportation & Storage | K3: Accommodation | L3: Food & Beverage Services | M3: Information & Communications | N3: Finance & Insurance | O3: Real estate | P3: Ownership of Dwellings | Q3: Professional Services | R3: Administrative & Support Services | S3: Public Administration & Defence | T3: Education | U3: Health & Social Services | V3: Arts, Entertainment & Recreation | W3: Other Services – Others | X3: Total intermediate use at basic prices | Y3: PURCHASES BY FINAL DEMAND | Z3: Household and NPISHs final consumption expenditure | AA3: Government final consumption expenditure | AB3: Gross fixed capital formation | AC3: Changes in inventories | AD3: Exports of goods & services | AE3: Total final output at basic prices | AF3: Total output at basic prices
A4: 1 | B4: Agriculture, Fishing, Quarrying, Utilities and Sewerage & Waste Management | C4: Other Goods Industries | D4: 65.9506 | E4: 13.9053 | F4: 31.3789 | G4: 1.2208 | H4: 1.8026 | I4: 0.1782 | J4: 2.1367 | K4: 2.7454 | L4: 45.3679 | M4: 2.1516 | N4: 0.6307 | O4: 0.4215 | P4: 0.0468 | Q4: 1.1468 | R4: 0.5075 | S4: 0.4169 | T4: 0.0844 | U4: 0.2706 | V4: 0.3159 | W4: 0.3856 | X4: 171.0646 | Z4: 104.4694 | AA4: 0.0493 | AB4: 1.2829 | AC4: -10.7868 | AD4: 155.3793 | AE4: 250.3941 | AF4: 421.4588 | AH4: 462.3994 | AI4: =AE4-AH4 -> -212.0053 | AK4: =AD4+Z4 -> 259.8487 | AL4: =AK4/AE4 -> 1.0377589
A5: 3 | B5: Agriculture, Fishing, Quarrying, Utilities and Sewerage & Waste Management | C5: Utilities | D5: 17.8389 | E5: 4211.1339 | F5: 2954.1032 | G5: 197.7333 | H5: 521.8414 | I5: 326.452 | J5: 565.4802 | K5: 255.9576 | L5: 604.236 | M5: 575.2965 | N5: 300.2012 | O5: 709.2538 | P5: 5.2231 | Q5: 249.4537 | R5: 68.9394 | S5: 1443.5385 | T5: 252.5453 | U5: 263.3583 | V5: 261.2971 | W5: 122.377 | X5: 13906.26 | Z5: 1984.9173 | AA5: 436.7096 | AB5: 111.1044 | AC5: 31.0993 | AD5: 1286.6126 | AE5: 3850.4433 | AF5: 17756.704 | AH5: 303978 | AI5: =AE5-AH5 -> -300127.55 | AK5: =AD5+Z5 -> 3271.5299 | AL5: =AK5/AE5 -> 0.84965019
A6: 2 | B6: Manufacturing | C6: Manufacturing | D6: 21.78 | E6: 477.1356 | F6: 59777.284 | G6: 4939.7923 | H6: 4653.438 | I6: 295.0777 | J6: 10705.636 | K6: 364.2118 | L6: 1701.2488 | M6: 5668.1522 | N6: 870.4004 | O6: 1088.8395 | P6: 56.8557 | Q6: 3939.3144 | R6: 1489.8285 | S6: 1530.5964 | T6: 546.6211 | U6: 1438.6701 | V6: 283.6726 | W6: 384.067 | X6: 100232.62 | Z6: 4764.5359 | AA6: 264.3985 | AB6: 9283.9755 | AC6: 1722.4049 | AD6: 241832.92 | AE6: 257868.24 | AF6: 358100.86 | AH6: 4044.6337 | AI6: =AE6-AH6 -> 253823.6 | AK6: =AD6+Z6 -> 246597.46 | AL6: =AK6/AE6 -> 0.95629249
A7: 4 | B7: Construction | C7: Construction | D7: 0.2448 | E7: 166.7291 | F7: 498.1525 | G7: 23583.028 | H7: 127.1551 | I7: 46.2609 | J7: 198.9144 | K7: 87.0786 | L7: 47.9118 | M7: 74.7246 | N7: 116.4518 | O7: 691.2068 | P7: 1759.0047 | Q7: 336.3871 | R7: 29.7638 | S7: 194.5632 | T7: 113.6001 | U7: 68.0004 | V7: 95.0039 | W7: 10.2856 | X7: 28244.467 | Z7: 31.907 | AA7: 5.6617 | AB7: 32445.845 | AC7: 0 | AD7: 1735.3274 | AE7: 34218.741 | AF7: 62463.208 | AH7: 34806.097 | AI7: =AE7-AH7 -> -587.3561 | AK7: =AD7+Z7 -> 1767.2344 | AL7: =AK7/AE7 -> 0.051645219
A8: 5 | B8: Wholesale & Retail Trade | C8: Wholesale Trade | D8: 21.5694 | E8: 216.5662 | F8: 11955.634 | G8: 1600.1345 | H8: 5469.2765 | I8: 414.0447 | J8: 3575.0687 | K8: 372.6969 | L8: 847.8851 | M8: 4743.8474 | N8: 1447.849 | O8: 452.6748 | P8: 50.3802 | Q8: 993.069 | R8: 554.6467 | S8: 752.27 | T8: 208.3392 | U8: 521.8167 | V8: 133.0535 | W8: 133.8957 | X8: 34464.718 | Z8: 4611.3589 | AA8: 88.9062 | AB8: 4957.9054 | AC8: 3.122 | AD8: 154400.67 | AE8: 164061.96 | AF8: 198526.68 | AH8: 209881.89 | AI8: =AE8-AH8 -> -45819.93 | AK8: =AD8+Z8 -> 159012.02 | AL8: =AK8/AE8 -> 0.96921935
A9: 6 | B9: Wholesale & Retail Trade | C9: Retail Trade | D9: 0.1111 | E9: 4.1732 | F9: 58.3435 | G9: 165.415 | H9: 543.575 | I9: 304.5411 | J9: 158.9899 | K9: 7.6643 | L9: 44.4384 | M9: 110.3385 | N9: 66.4355 | O9: 35.7542 | P9: 5.0209 | Q9: 67.063 | R9: 33.0546 | S9: 58.6408 | T9: 21.3925 | U9: 52.6262 | V9: 14.8224 | W9: 16.0478 | X9: 1768.4478 | Z9: 11265.522 | AA9: 5.1791 | AB9: 112.348 | AC9: 0 | AD9: 2990.4144 | AE9: 14373.464 | AF9: 16141.911 | AH9: 13049.675 | AI9: =AE9-AH9 -> 1323.7888 | AK9: =AD9+Z9 -> 14255.937 | AL9: =AK9/AE9 -> 0.99182333
A10: 7 | B10: Transportation & Storage | C10: Transportation & Storage | D10: 10.376 | E10: 148.7109 | F10: 3130.9802 | G10: 297.3026 | H10: 21302.257 | I10: 862.1098 | J10: 42265.813 | K10: 48.9309 | L10: 182.0345 | M10: 1196.7248 | N10: 1063.5047 | O10: 468.045 | P10: 11.6593 | Q10: 554.6505 | R10: 348.1139 | S10: 1936.949 | T10: 145.0296 | U10: 123.9488 | V10: 66.8032 | W10: 70.9375 | X10: 74234.881 | Z10: 8152.9352 | AA10: 100.1712 | AB10: 532.5968 | AC10: 2.7954 | AD10: 88862.436 | AE10: 97650.934 | AF10: 171885.82 | AH10: 145226.4 | AI10: =AE10-AH10 -> -47575.471 | AK10: =AD10+Z10 -> 97015.371 | AL10: =AK10/AE10 -> 0.99349148
A11: 8 | B11: Accommodation & Food Services | C11: Accommodation | D11: 0.4708 | E11: 5.631 | F11: 111.9679 | G11: 12.1122 | H11: 197.8331 | I11: 45.6136 | J11: 241.3463 | K11: 6.1154 | L11: 36.3508 | M11: 201.4309 | N11: 247.2624 | O11: 38.3991 | P11: 0.3549 | Q11: 153.2875 | R11: 58.7629 | S11: 65.7349 | T11: 27.7754 | U11: 18.031 | V11: 18.5994 | W11: 16.0787 | X11: 1503.1582 | Z11: 1468.9627 | AA11: 7.0207 | AB11: 46.9631 | AC11: 0 | AD11: 4591.7564 | AE11: 6114.7029 | AF11: 7617.8614 | AH11: 2937.2326 | AI11: =AE11-AH11 -> 3177.4703 | AK11: =AD11+Z11 -> 6060.7191 | AL11: =AK11/AE11 -> 0.99117148
A12: 9 | B12: Accommodation & Food Services | C12: Food & Beverage Services | D12: 3.5709 | E12: 11.1499 | F12: 245.4118 | G12: 30.8675 | H12: 631.5546 | I12: 83.7126 | J12: 839.2108 | K12: 21.6157 | L12: 172.9573 | M12: 600.8016 | N12: 567.6708 | O12: 107.0078 | P12: 0.4363 | Q12: 249.5936 | R12: 154.9079 | S12: 98.093 | T12: 69.1138 | U12: 55.1231 | V12: 66.3183 | W12: 45.2446 | X12: 4054.3618 | Z12: 8304.7973 | AA12: 1.222 | AB12: 72.4567 | AC12: 0 | AD12: 3110.6959 | AE12: 11489.172 | AF12: 15543.534 | AH12: 9783.783 | AI12: =AE12-AH12 -> 1705.3889 | AK12: =AD12+Z12 -> 11415.493 | AL12: =AK12/AE12 -> 0.99358712
A13: 10 | B13: Information & Communications | C13: Information & Communications | D13: 1.7567 | E13: 142.8558 | F13: 986.5946 | G13: 201.1621 | H13: 2285.8993 | I13: 343.1373 | J13: 1146.7963 | K13: 88.5457 | L13: 109.3291 | M13: 15884.646 | N13: 5275.3036 | O13: 569.5432 | P13: 28.3509 | Q13: 2836.0512 | R13: 441.8578 | S13: 1751.1836 | T13: 374.5206 | U13: 673.5069 | V13: 258.2058 | W13: 160.5523 | X13: 33559.798 | Z13: 5351.8589 | AA13: 98.2635 | AB13: 5809.1774 | AC13: 0.2992 | AD13: 57475.088 | AE13: 68734.687 | AF13: 102294.49 | AH13: 96543.314 | AI13: =AE13-AH13 -> -27808.627 | AK13: =AD13+Z13 -> 62826.947 | AL13: =AK13/AE13 -> 0.91405009
A14: 11 | B14: Financial & Insurance Services | C14: Finance & Insurance | D14: 9.9512 | E14: 270.9357 | F14: 3035.8696 | G14: 729.1418 | H14: 6618.7803 | I14: 709.3797 | J14: 1923.0112 | K14: 237.6112 | L14: 214.7188 | M14: 1327.7354 | N14: 23279.188 | O14: 3063.5364 | P14: 1301.1242 | Q14: 1510.8932 | R14: 726.5017 | S14: 4670.9831 | T14: 217.8836 | U14: 406.1082 | V14: 214.3557 | W14: 138.2835 | X14: 50605.992 | Z14: 20750.338 | AA14: 429.3211 | AB14: 597.4825 | AC14: 0 | AD14: 64379.87 | AE14: 86157.011 | AF14: 136763 | AH14: 95228.888 | AI14: =AE14-AH14 -> -9071.8776 | AK14: =AD14+Z14 -> 85130.207 | AL14: =AK14/AE14 -> 0.98808218
A15: 12 | B15: Real Estate Services | C15: Real estate | D15: 0.5034 | E15: 157.275 | F15: 1053.168 | G15: 251.3436 | H15: 2792.5309 | I15: 3165.2495 | J15: 1520.604 | K15: 421.7004 | L15: 1305.2927 | M15: 1003.4982 | N15: 2653.1496 | O15: 2214.5739 | P15: 16.1146 | Q15: 1169.8375 | R15: 458.988 | S15: 634.1172 | T15: 402.018 | U15: 729.5589 | V15: 236.4339 | W15: 338.4024 | X15: 20524.36 | Z15: 2371.8929 | AA15: 141.0614 | AB15: 7888.522 | AC15: 0.0011 | AD15: 1455.3226 | AE15: 11856.8 | AF15: 32381.159 | AH15: 12242.788 | AI15: =AE15-AH15 -> -385.9882 | AK15: =AD15+Z15 -> 3827.2155 | AL15: =AK15/AE15 -> 0.32278654
... A23: 20 | B23: Other Community, Social & Personal Services | C23: Other Services – Others | D23: 0.7935 | E23: 30.0257 | F23: 130.0949 | G23: 95.4063 | H23: 171.5493 | I23: 96.0753 | J23: 411.6018 | K23: 52.4971 | L23: 27.3364 | M23: 225.0088 | N23: 252.3049 | O23: 51.9643 | P23: 79.8861 | Q23: 127.3923 | R23: 85.1843 | S23: 361.2434 | T23: 102.9042 | U23: 107.4022 | V23: 139.9418 | W23: 74.0756 | X23: 2622.6884 | Z23: 5758.3582 | AA23: 59.6688 | AB23: 70.4172 | AC23: 0 | AD23: 1098.3795 | AE23: 6986.8236 | AF23: 9609.5117 | AH23: 6468.8833 | AI23: =AE23-AH23 -> 517.9403 | AK23: =AD23+Z23 -> 6856.7377 | AL23: =AK23/AE23 -> 0.98138125
A24: RT1 | C24: Total domestic use at basic prices | D24: 168.0495 | E24: 6495.301 | F24: 92893.802 | G24: 34473.765 | H24: 54987.107 | I24: 7906.815 | J24: 69107.682 | K24: 2517.5987 | L24: 5994.8145 | M24: 37378.818 | N24: 42738.58 | O24: 14927.79 | P24: 3930.902 | Q24: 16495.296 | R24: 6998.9697 | S24: 16924.699 | T24: 3671.6366 | U24: 6978.3517 | V24: 3139.5581 | W24: 1940.8648 | X24: 429670.4 | Z24: 116958.27 | AA24: 52648.889 | AB24: 70136.996 | AC24: 1761.9618 | AD24: 664348.95 | AE24: 905855.07 | AF24: 1335525.5 | AK24: =AD24+Z24 -> 781307.22 | AL24: =AK24/AE24 -> 0.86250798
A25: 21 | C25: Imports of goods and services | D25: 86.8273 | E25: 5343.4202 | F25: 165120.71 | G25: 10003.008 | H25: 59580.845 | I25: 627.5191 | J25: 70648.137 | K25: 825.6186 | L25: 3489.2231 | M25: 42107.402 | N25: 25510.168 | O25: 493.6332 | P25: 0 | Q25: 15529.907 | R25: 3110.9042 | S25: 7314.8157 | T25: 1346.5244 | U25: 2785.8874 | V25: 641.5108 | W25: 949.8987 | X25: 415515.95 | Z25: 47588.063 | AA25: 0 | AB25: 42944.23 | AC25: 7311.3612 | AD25: 245965.19 | AE25: 343808.85 | AF25: 759324.8
A26: 22 | C26: Taxes less subsidies on products | D26: 1.1825 | E26: 33.1967 | F26: 114.6539 | G26: 22.1007 | H26: 79.1954 | I26: 13.5508 | J26: 418.4051 | K26: 19.1256 | L26: 327.648 | M26: 157.9929 | N26: 337.657 | O26: 189.8057 | P26: 0 | Q26: 73.1313 | R26: 27.426 | S26: 115.1831 | T26: 50.3616 | U26: 180.9264 | V26: 43.3314 | W26: 11.7649 | X26: 2216.6393 | Z26: 18340.384 | AA26: 0 | AB26: 5386.4541 | AC26: 0 | AD26: 0 | AE26: 23726.838 | AF26: 25943.477
A27: RT2 | C27: Total use at purchasers' prices | D27: 256.0589 | E27: 11871.918 | F27: 258129.17 | G27: 44498.874 | H27: 114647.15 | I27: 8547.8851 | J27: 140174.22 | K27: 3362.3428 | L27: 9811.6856 | M27: 79644.213 | N27: 68586.403 | O27: 15611.229 | P27: 3930.902 | Q27: 32098.334 | R27: 10137.3 | S27: 24354.699 | T27: 5068.5218 | U27: 9945.166 | V27: 3824.3999 | W27: 2902.5285 | X27: 847403 | Z27: 182886.72 | AA27: 52648.889 | AB27: 118467.68 | AC27: 9073.323 | AD27: 910314.14 | AE27: 1273390.8 | AF27: 2120793.7
A28: 23 | C28: Compensation of employees | D28: 76.6999 | E28: 1586.9297 | F28: 26493.853 | G28: 12061.339 | H28: 24486.845 | I28: 4861.57 | J28: 13830.329 | K28: 1895.5612 | L28: 3742.8287 | M28: 13514.796 | N28: 27506.144 | O28: 3236.3738 | P28: 0 | Q28: 20303.107 | R28: 8034.729 | S28: 12583.74 | T28: 11739.158 | U28: 10754.511 | V28: 2331.3116 | W28: 5229.0092 | X28: 204268.84 | Z28: 0 | AA28: 0 | AB28: 0 | AC28: 0 | AD28: 0 | AE28: 0 | AF28: 204268.84
A29: 24 | C29: Other taxes less subsidies on production | D29: 10.9 | E29: 285.2 | F29: 1165.9002 | G29: 2000.4 | H29: 380.8 | I29: 208 | J29: 712.4998 | K29: 222.3 | L29: 233.5 | M29: 273.4 | N29: 120.1001 | O29: 1719.7 | P29: 940 | Q29: 230.9001 | R29: 262.8002 | S29: 35.8904 | T29: -47.7462 | U29: 88.5076 | V29: 299.2452 | W29: 503.1029 | X29: 9645.4 | Z29: 0 | AA29: 0 | AB29: 0 | AC29: 0 | AD29: 0 | AE29: 0 | AF29: 9645.4
A30: 25 | C30: Gross operating surplus | D30: 77.7999 | E30: 4012.6567 | F30: 72311.945 | G30: 3902.5947 | H30: 59011.885 | I30: 2524.4563 | J30: 17168.762 | K30: 2137.6574 | L30: 1755.5193 | M30: 8862.0758 | N30: 40550.357 | O30: 11813.856 | P30: 17512.998 | Q30: 8988.0388 | R30: 13441.317 | S30: 385.9697 | T30: 2944.3493 | U30: 2308.7598 | V30: 3522.3706 | W30: 974.8712 | X30: 274208.24 | Z30: 0 | AA30: 0 | AB30: 0 | AC30: 0 | AD30: 0 | AE30: 0 | AF30: 274208.24
A31: RT3 | C31: Value added at basic prices | D31: 165.3998 | E31: 5884.7864 | F31: 99971.698 | G31: 17964.334 | H31: 83879.529 | I31: 7594.0263 | J31: 31711.591 | K31: 4255.5186 | L31: 5731.848 | M31: 22650.272 | N31: 68176.601 | O31: 16769.93 | P31: 18452.998 | Q31: 29522.046 | R31: 21738.846 | S31: 13005.6 | T31: 14635.762 | U31: 13151.779 | V31: 6152.9274 | W31: 6706.9833 | X31: 488122.48 | Z31: 0 | AA31: 0 | AB31: 0 | AC31: 0 | AD31: 0 | AE31: 0 | AF31: 488122.48
A32: RT4 | C32: Total inputs at basic prices | D32: 421.4588 | E32: 17756.704 | F32: 358100.86 | G32: 62463.208 | H32: 198526.68 | I32: 16141.911 | J32: 171885.82 | K32: 7617.8614 | L32: 15543.534 | M32: 102294.49 | N32: 136763 | O32: 32381.159 | P32: 22383.9 | Q32: 61620.38 | R32: 31876.146 | S32: 37360.299 | T32: 19704.283 | U32: 23096.945 | V32: 9977.3275 | W32: 9609.5117 | X32: 1335525.5 | Z32: 182886.72 | AA32: 52648.889 | AB32: 118467.68 | AC32: 9073.323 | AD32: 910314.14 | AE32: 1273390.8 | AF32: 2608916.2

Sheet updated 2021 IO table
D1: 1 | E1: 3 | F1: 2 | G1: 4 | H1: 5 | I1: 6 | J1: 7 | K1: 8 | L1: 9 | M1: 10 | N1: 11 | O1: 12 | P1: 13 | Q1: 14 | R1: 15 | S1: 16 | T1: 17 | U1: 18 | V1: 19 | W1: 20 | X1: CT1 | Z1: 21 | AA1: 22 | AB1: 23 | AC1: 24 | AD1: 25 | AE1: CT2 | AF1: CT3
D2: Agriculture, Fishing, Quarrying, Utilities and Sewerage & Waste Management | E2: Agriculture, Fishing, Quarrying, Utilities and Sewerage & Waste Management | F2: Manufacturing | G2: Construction | H2: Wholesale & Retail Trade | I2: Wholesale & Retail Trade | J2: Transportation & Storage | K2: Accommodation & Food Services | L2: Accommodation & Food Services | M2: Information & Communications | N2: Financial & Insurance Services | O2: Real Estate Services | P2: Real Estate Services | Q2: Professional Services | R2: Administrative & Support Services | S2: Public Administration & Education | T2: Public Administration & Education | U2: Health & Social Services | V2: Arts, Entertainment & Recreation | W2: Other Community, Social & Personal Services
D3: Other Goods Industries | E3: Utilities | F3: Manufacturing | G3: Construction | H3: Wholesale Trade | I3: Retail Trade | J3: Transportation & Storage | K3: Accommodation | L3: Food & Beverage Services | M3: Information & Communications | N3: Finance & Insurance | O3: Real estate | P3: Ownership of Dwellings | Q3: Professional Services | R3: Administrative & Support Services | S3: Public Administration & Defence | T3: Education | U3: Health & Social Services | V3: Arts, Entertainment & Recreation | W3: Other Services – Others | X3: Total intermediate use at basic prices | Y3: PURCHASES BY FINAL DEMAND | Z3: Household and NPISHs final consumption expenditure | AA3: Government final consumption expenditure | AB3: Gross fixed capital formation | AC3: Changes in inventories | AD3: Exports of goods & services | AE3: Total final output at basic prices | AF3: Total output at basic prices
A4: 1 | B4: Agriculture, Fishing, Quarrying, Utilities and Sewerage & Waste Management | C4: Other Goods Industries | D4: 97.6844 | E4: 87.221 | F4: 21.6182 | G4: 5.1901 | H4: 2.6777 | I4: 0.3853 | J4: 5.0028 | K4: 9.491 | L4: 78.9236 | M4: 2.3322 | N4: 1.0947 | O4: 0.6811 | P4: 0.0745 | Q4: 0.8004 | R4: 4.3105 | S4: 2.0623 | T4: 0.2805 | U4: 0.9942 | V4: 0.7552 | W4: 1.5081 | X4: 323.0879 | Z4: 177.4336 | AA4: 0.0727 | AB4: 2.5781 | AC4: -0.5868 | AD4: 282.9019 | AE4: 462.3994 | AF4: 785.4875
A5: 3 | B5: Agriculture, Fishing, Quarrying, Utilities and Sewerage & Waste Management | C5: Utilities | D5: 44.5401 | E5: 70396.561 | F5: 355.5129 | G5: 4862.0761 | H5: 5328.2007 | I5: 395.7432 | J5: 12512.856 | K5: 212.4627 | L5: 1526.1045 | M5: 5072.7353 | N5: 684.5946 | O5: 1466.371 | P5: 30.2451 | Q5: 4242.7546 | R5: 1395.4328 | S5: 2134.9059 | T5: 593.3606 | U5: 2055.4584 | V5: 220.9156 | W5: 452.1684 | X5: 113983 | Z5: 6015.749 | AA5: 818.6686 | AB5: 9317.1969 | AC5: -300.7154 | AD5: 288127.1 | AE5: 303978 | AF5: 417961
A6: 2 | B6: Manufacturing | C6: Manufacturing | D6: 60.9523 | E6: 2868.2783 | F6: 3585.4285 | G6: 196.3921 | H6: 415.0529 | I6: 395.6144 | J6: 731.7367 | K6: 234.1209 | L6: 637.3023 | M6: 1141.6899 | N6: 436.8957 | O6: 760.1067 | P6: 1.6167 | Q6: 328.4017 | R6: 68.0006 | S6: 1574.8613 | T6: 277.7387 | U6: 340.7714 | V6: 258.1997 | W6: 126.1002 | X6: 14439.261 | Z6: 2507.1797 | AA6: 579.2191 | AB6: 56.0613 | AC6: -82.9774 | AD6: 985.151 | AE6: 4044.6337 | AF6: 18483.894
A7: 4 | B7: Construction | C7: Construction | D7: 1.3787 | E7: 395.084 | F7: 87.589 | G7: 21823.758 | H7: 159.1063 | I7: 33.8986 | J7: 267.3183 | K7: 70.0638 | L7: 39.1807 | M7: 101.1271 | N7: 97.7009 | O7: 760.1231 | P7: 1398.4304 | Q7: 565.0981 | R7: 38.4452 | S7: 197.7908 | T7: 116.796 | U7: 67.6021 | V7: 67.4145 | W7: 13.1923 | X7: 26301.098 | Z7: 25.3587 | AA7: 4.1436 | AB7: 33517.276 | AC7: 0 | AD7: 1259.3185 | AE7: 34806.097 | AF7: 61107.196
A8: 5 | B8: Wholesale & Retail Trade | C8: Wholesale Trade | D8: 68.871 | E8: 14054.25 | F8: 165.5831 | G8: 1990.2075 | H8: 4805.4783 | I8: 366.7311 | J8: 5843.1712 | K8: 138.7063 | L8: 687.6269 | M8: 5665.486 | N8: 1076.0765 | O8: 442.0828 | P8: 34.6188 | Q8: 1120.9424 | R8: 467.4693 | S8: 1518.6727 | T8: 265.4476 | U8: 642.9962 | V8: 110.6991 | W8: 211.2716 | X8: 39676.389 | Z8: 7457.1688 | AA8: 86.3626 | AB8: 5450.2849 | AC8: -0.7815 | AD8: 196888.85 | AE8: 209881.89 | AF8: 249558.28
A9: 6 | B9: Wholesale & Retail Trade | C9: Retail Trade | D9: 0.2515 | E9: 70.4416 | F9: 4.5977 | G9: 214.3577 | H9: 524.2712 | I9: 230.3392 | J9: 228.005 | K9: 5.1914 | L9: 153.0098 | M9: 222.9619 | N9: 78.1325 | O9: 48.2787 | P9: 3.4966 | Q9: 108.2861 | R9: 35.2576 | S9: 150.0523 | T9: 28.7063 | U9: 67.756 | V9: 13.931 | W9: 27.3088 | X9: 2214.6328 | Z9: 11656.371 | AA9: 10.6665 | AB9: 140.4975 | AC9: 0 | AD9: 1242.1405 | AE9: 13049.675 | AF9: 15264.308
A10: 7 | B10: Transportation & Storage | C10: Transportation & Storage | D10: 9.7619 | E10: 2521.8041 | F10: 109.8131 | G10: 236.7421 | H10: 24658.315 | I10: 666.437 | J10: 79642.327 | K10: 23.1531 | L10: 91.9332 | M10: 1620.908 | N10: 823.4893 | O10: 403.981 | P10: 34.5172 | Q10: 445.2801 | R10: 494.7555 | S10: 2706.3841 | T10: 91.3204 | U10: 142.6469 | V10: 63.333 | W10: 53.7776 | X10: 114840.68 | Z10: 6002.1411 | AA10: 46.4959 | AB10: 232.0372 | AC10: -0.302 | AD10: 138946.03 | AE10: 145226.4 | AF10: 260067.08
A11: 8 | B11: Accommodation & Food Services | C11: Accommodation | D11: 0.0964 | E11: 53.7392 | F11: 9.8355 | G11: 61.3597 | H11: 141.3523 | I11: 64.0218 | J11: 437.5832 | K11: 3.6412 | L11: 23.5359 | M11: 104.8144 | N11: 158.6432 | O11: 21.0473 | P11: 0.1812 | Q11: 123.3064 | R11: 50.0269 | S11: 81.0936 | T11: 17.7247 | U11: 14.4858 | V11: 14.9424 | W11: 17.3528 | X11: 1398.7838 | Z11: 2098.3746 | AA11: 109.195 | AB11: 48.5862 | AC11: 0 | AD11: 681.0768 | AE11: 2937.2326 | AF11: 4336.0165
A12: 9 | B12: Accommodation & Food Services | C12: Food & Beverage Services | D12: 1.1318 | E12: 74.686 | F12: 16.7224 | G12: 59.1297 | H12: 489.1515 | I12: 72.8334 | J12: 768.7048 | K12: 7.0638 | L12: 73.2845 | M12: 215.9257 | N12: 714.5129 | O12: 50.8268 | P12: 0.5425 | Q12: 155.8814 | R12: 70.9334 | S12: 95.8801 | T12: 33.2543 | U12: 39.7105 | V12: 30.6616 | W12: 22.5965 | X12: 2993.4337 | Z12: 8884.7111 | AA12: 5.4982 | AB12: 46.3927 | AC12: 0 | AD12: 847.1809 | AE12: 9783.783 | AF12: 12777.217
A13: 10 | B13: Information & Communications | C13: Information & Communications | D13: 4.6582 | E13: 1667.5938 | F13: 236.125 | G13: 282.3433 | H13: 5098.2262 | I13: 422.8942 | J13: 2065.1096 | K13: 94.9026 | L13: 149.2372 | M13: 35361.026 | N13: 5734.1584 | O13: 995.1886 | P13: 47.7574 | Q13: 3413.617 | R13: 582.912 | S13: 2569.8275 | T13: 604.1854 | U13: 881.4769 | V13: 313.3162 | W13: 193.9254 | X13: 60718.481 | Z13: 4987.1013 | AA13: 284.9416 | AB13: 6392.4461 | AC13: -0.0197 | AD13: 84878.845 | AE13: 96543.314 | AF13: 157261.8
A14: 11 | B14: Financial & Insurance Services | C14: Finance & Insurance | D14: 4.9185 | E14: 2099.9051 | F14: 312.4429 | G14: 508.5516 | H14: 9129.2848 | I14: 713.735 | J14: 2198.3664 | K14: 179.0606 | L14: 206.8769 | M14: 2548.5654 | N14: 25704.34 | O14: 3760.374 | P14: 2280.6058 | Q14: 1635.5499 | R14: 719.3892 | S14: 5293.0698 | T14: 226.0806 | U14: 362.6437 | V14: 178.9246 | W14: 139.6902 | X14: 58202.374 | Z14: 23323.649 | AA14: 583.4589 | AB14: 841.5357 | AC14: 0 | AD14: 70480.245 | AE14: 95228.888 | AF14: 153431.26
A15: 12 | B15: Real Estate Services | C15: Real estate | D15: 0.9835 | E15: 1067.7104 | F15: 171.1844 | G15: 251.0616 | H15: 3880.9663 | I15: 2466.3354 | J15: 1205.8458 | K15: 251.4535 | L15: 1157.8298 | M15: 1832.0038 | N15: 2063.9159 | O15: 2042.6171 | P15: 5.6398 | Q15: 1504.6507 | R15: 525.3713 | S15: 690.329 | T15: 431.7099 | U15: 751.7993 | V15: 413.557 | W15: 480.6028 | X15: 21195.567 | Z15: 2495.3738 | AA15: 47.783 | AB15: 8796.7465 | AC15: -0.0001 | AD15: 902.885 | AE15: 12242.788 | AF15: 33438.355
... A23: 20 | B23: Other Community, Social & Personal Services | C23: Other Services – Others | D23: 0.9978 | E23: 92.4883 | F23: 31.3221 | G23: 70.1822 | H23: 177.5884 | I23: 63.0819 | J23: 370.1575 | K23: 32.6719 | L23: 16.0899 | M23: 273.9497 | N23: 185.138 | O23: 57.3611 | P23: 53.5599 | Q23: 132.506 | R23: 71.2003 | S23: 527.0691 | T23: 121.9666 | U23: 131.3745 | V23: 89.0104 | W23: 94.5301 | X23: 2592.2458 | Z23: 6072.0865 | AA23: 63.5923 | AB23: 50.3783 | AC23: 0 | AD23: 282.8262 | AE23: 6468.8833 | AF23: 9061.1292
A24: RT1 | C24: Total domestic use at basic prices | D24: 304.8402 | E24: 100750.61 | F24: 5626.8191 | G24: 32640.585 | H24: 65840.336 | I24: 6981.8559 | J24: 112927.48 | K24: 1619.8525 | L24: 5335.6553 | M24: 62000.298 | N24: 43291.121 | O24: 15572.488 | P24: 4304.5999 | Q24: 19554.146 | R24: 7275.7743 | S24: 21138.181 | T24: 4220.2224 | U24: 8546.934 | V24: 2921.362 | W24: 2266.3087 | X24: 523119.47 | Z24: 128734.7 | AA24: 61847.753 | AB24: 72920.074 | AC24: -388.3131 | AD24: 820978.16 | AE24: 1084092.4 | AF24: 1607211.8
A25: 21 | C25: Imports of goods and services | D25: 301.3626 | E25: 198664.11 | F25: 6289.7383 | G25: 11438.824 | H25: 76984.555 | I25: 1094.2933 | J25: 93938.285 | K25: 496.968 | L25: 2840.2682 | M25: 64506.33 | N25: 34345.269 | O25: 964.095 | P25: 0 | Q25: 16716.892 | R25: 2859.1561 | S25: 8726.8974 | T25: 1427.9778 | U25: 2813.5143 | V25: 487.1224 | W25: 983.479 | X25: 525879.14 | Z25: 25176.557 | AA25: 0 | AB25: 47210.109 | AC25: 10427.513 | AD25: 263073.09 | AE25: 345887.27 | AF25: 871766.41
A26: 22 | C26: Taxes less subsidies on products | D26: 1.2853 | E26: 197.6219 | F26: 219.0937 | G26: 40.1737 | H26: 118.3131 | I26: 29.0578 | J26: 592.9452 | K26: 29.6992 | L26: 361.5836 | M26: 733.8054 | N26: 1924.5075 | O26: 444.5389 | P26: 0 | Q26: 128.5792 | R26: 43.6977 | S26: 206.9068 | T26: 46.6879 | U26: 227.1945 | V26: 48.6234 | W26: 13.4354 | X26: 5407.7501 | Z26: 16296.625 | AA26: 0 | AB26: 8711.6252 | AC26: 0 | AD26: 0 | AE26: 25008.25 | AF26: 30416
A27: RT2 | C27: Total use at purchasers' prices | D27: 607.4879 | E27: 299612.34 | F27: 12135.652 | G27: 44119.583 | H27: 142943.2 | I27: 8105.2076 | J27: 207458.71 | K27: 2146.5196 | L27: 8537.507 | M27: 127240.43 | N27: 79560.897 | O27: 16981.121 | P27: 4304.5999 | Q27: 36399.618 | R27: 10178.627 | S27: 30071.985 | T27: 5694.8877 | U27: 11587.643 | V27: 3457.1079 | W27: 3263.2245 | X27: 1054406.4 | Z27: 170207.88 | AA27: 61847.753 | AB27: 128841.81 | AC27: 10039.2 | AD27: 1084051.3 | AE27: 1454987.9 | AF27: 2509394.2
A28: 23 | C28: Compensation of employees | D28: 84.1 | E28: 26753.218 | F28: 1753.2 | G28: 12351.519 | H28: 24528.2 | I28: 4734.2447 | J28: 13382.692 | K28: 1414.8438 | L28: 3771.5428 | M28: 19208.101 | N28: 30821.251 | O28: 3145.4212 | P28: 0 | Q28: 21996.529 | R28: 8638.5684 | S28: 13760.317 | T28: 12374.2 | U28: 12784.123 | V28: 2071.0971 | W28: 5336.374 | X28: 218909.54 | Z28: 0 | AA28: 0 | AB28: 0 | AC28: 0 | AD28: 0 | AE28: 0 | AF28: 218909.54
A29: 24 | C29: Other taxes less subsidies on production | D29: 1.3999 | E29: -327.8002 | F29: 283.2 | G29: 307.9 | H29: -642.4 | I29: -690.3 | J29: -645.4001 | K29: -192.3 | L29: -1249.9 | M29: -206.7 | N29: -321.9999 | O29: 1339 | P29: 992.5 | Q29: -815.5999 | R29: -545.2999 | S29: 39.1 | T29: -358.9 | U29: -514.9 | V29: -178.2 | W29: 155.8 | X29: -3570.8 | Z29: 0 | AA29: 0 | AB29: 0 | AC29: 0 | AD29: 0 | AE29: 0 | AF29: -3570.8
A30: 25 | C30: Gross operating surplus | D30: 92.5 | E30: 91923.237 | F30: 4311.8424 | G30: 4328.1949 | H30: 82729.271 | I30: 3115.156 | J30: 39871.083 | K30: 966.9534 | L30: 1718.0672 | M30: 11019.96 | N30: 43371.113 | O30: 11972.813 | P30: 17920.4 | Q30: 8490.3332 | R30: 8393.48 | S30: 537.6659 | T30: 3206.6353 | U30: 1580.6208 | V30: 1611.6869 | W30: 305.7313 | X30: 337466.74 | Z30: 0 | AA30: 0 | AB30: 0 | AC30: 0 | AD30: 0 | AE30: 0 | AF30: 337466.74
A31: RT3 | C31: Value added at basic prices | D31: 177.9999 | E31: 118348.66 | F31: 6348.2424 | G31: 16987.614 | H31: 106615.07 | I31: 7159.1007 | J31: 52608.375 | K31: 2189.4972 | L31: 4239.71 | M31: 30021.361 | N31: 73870.365 | O31: 16457.234 | P31: 18912.9 | Q31: 29671.262 | R31: 16486.749 | S31: 14337.083 | T31: 15221.935 | U31: 13849.844 | V31: 3504.584 | W31: 5797.9053 | X31: 552805.49 | AA31: 0 | AB31: 0 | AC31: 0 | AD31: 0 | AE31: 0 | AF31: 552805.49
A32: RT4 | C32: Total inputs at basic prices | D32: 785.4875 | E32: 417961 | F32: 18483.894 | G32: 61107.196 | H32: 249558.28 | I32: 15264.308 | J32: 260067.08 | K32: 4336.0165 | L32: 12777.217 | M32: 157261.8 | N32: 153431.26 | O32: 33438.355 | P32: 23217.5 | Q32: 66070.879 | R32: 26665.375 | S32: 44409.068 | T32: 20916.823 | U32: 25437.487 | V32: 6961.6915 | W32: 9061.1292 | X32: 1607211.8 | Z32: 170207.88 | AA32: 61847.753 | AB32: 128841.81 | AC32: 10039.2 | AD32: 1084051.3 | AE32: 1454987.9 | AF32: 3062199.7

Sheet updated 2021 IO table (2)
D1: 1 | E1: 3 | F1: 2 | G1: 4 | H1: 5 | I1: 6 | J1: 7 | K1: 8 | L1: 9 | M1: 10 | N1: 11 | O1: 12 | P1: 13 | Q1: 14 | R1: 15 | S1: 16 | T1: 17 | U1: 18 | V1: 19 | W1: 20 | X1: CT1 | Z1: 21 | AA1: 22 | AB1: 23 | AC1: 24 | AD1: 25 | AE1: CT2 | AF1: CT3
D2: Agriculture, Fishing, Quarrying, Utilities and Sewerage & Waste Management | E2: Agriculture, Fishing, Quarrying, Utilities and Sewerage & Waste Management | F2: Manufacturing | G2: Construction | H2: Wholesale & Retail Trade | I2: Wholesale & Retail Trade | J2: Transportation & Storage | K2: Accommodation & Food Services | L2: Accommodation & Food Services | M2: Information & Communications | N2: Financial & Insurance Services | O2: Real Estate Services | P2: Real Estate Services | Q2: Professional Services | R2: Administrative & Support Services | S2: Public Administration & Education | T2: Public Administration & Education | U2: Health & Social Services | V2: Arts, Entertainment & Recreation | W2: Other Community, Social & Personal Services
D3: Other Goods Industries | E3: Utilities | F3: Manufacturing | G3: Construction | H3: Wholesale Trade | I3: Retail Trade | J3: Transportation & Storage | K3: Accommodation | L3: Food & Beverage Services | M3: Information & Communications | N3: Finance & Insurance | O3: Real estate | P3: Ownership of Dwellings | Q3: Professional Services | R3: Administrative & Support Services | S3: Public Administration & Defence | T3: Education | U3: Health & Social Services | V3: Arts, Entertainment & Recreation | W3: Other Services – Others | X3: Total intermediate use at basic prices | Y3: PURCHASES BY FINAL DEMAND | Z3: Household and NPISHs final consumption expenditure | AA3: Government final consumption expenditure | AB3: Gross fixed capital formation | AC3: Changes in inventories | AD3: Exports of goods & services | AE3: Total final output at basic prices | AF3: Total output at basic prices
B4: Agriculture, Fishing, Quarrying, Utilities and Sewerage & Waste Management
A5: 1 | B5: Agriculture, Fishing, Quarrying, Utilities and Sewerage & Waste Management | C5: Other Goods Industries | D5: 97.6844 | E5: 87.221 | F5: 21.6182 | G5: 5.1901 | H5: 2.6777 | I5: 0.3853 | J5: 5.0028 | K5: 9.491 | L5: 78.9236 | M5: 2.3322 | N5: 1.0947 | O5: 0.6811 | P5: 0.0745 | Q5: 0.8004 | R5: 4.3105 | S5: 2.0623 | T5: 0.2805 | U5: 0.9942 | V5: 0.7552 | W5: 1.5081 | X5: 323.0879 | Z5: 177.4336 | AA5: 0.0727 | AB5: 2.5781 | AC5: -0.5868 | AD5: 282.9019 | AE5: 462.3994 | AF5: 785.4875
A6: 3 | B6: Agriculture, Fishing, Quarrying, Utilities and Sewerage & Waste Management | C6: Utilities | D6: 44.5401 | E6: 70396.561 | F6: 355.5129 | G6: 4862.0761 | H6: 5328.2007 | I6: 395.7432 | J6: 12512.856 | K6: 212.4627 | L6: 1526.1045 | M6: 5072.7353 | N6: 684.5946 | O6: 1466.371 | P6: 30.2451 | Q6: 4242.7546 | R6: 1395.4328 | S6: 2134.9059 | T6: 593.3606 | U6: 2055.4584 | V6: 220.9156 | W6: 452.1684 | X6: 113983 | Z6: 6015.749 | AA6: 818.6686 | AB6: 9317.1969 | AC6: -300.7154 | AD6: 288127.1 | AE6: 303978 | AF6: 417961
A7: 2 | B7: Manufacturing | C7: Manufacturing | D7: 60.9523 | E7: 2868.2783 | F7: 3585.4285 | G7: 196.3921 | H7: 415.0529 | I7: 395.6144 | J7: 731.7367 | K7: 234.1209 | L7: 637.3023 | M7: 1141.6899 | N7: 436.8957 | O7: 760.1067 | P7: 1.6167 | Q7: 328.4017 | R7: 68.0006 | S7: 1574.8613 | T7: 277.7387 | U7: 340.7714 | V7: 258.1997 | W7: 126.1002 | X7: 14439.261 | Z7: 2507.1797 | AA7: 579.2191 | AB7: 56.0613 | AC7: -82.9774 | AD7: 985.151 | AE7: 4044.6337 | AF7: 18483.894
A8: 4 | B8: Construction | C8: Construction | D8: 1.3787 | E8: 395.084 | F8: 87.589 | G8: 21823.758 | H8: 159.1063 | I8: 33.8986 | J8: 267.3183 | K8: 70.0638 | L8: 39.1807 | M8: 101.1271 | N8: 97.7009 | O8: 760.1231 | P8: 1398.4304 | Q8: 565.0981 | R8: 38.4452 | S8: 197.7908 | T8: 116.796 | U8: 67.6021 | V8: 67.4145 | W8: 13.1923 | X8: 26301.098 | Z8: 25.3587 | AA8: 4.1436 | AB8: 33517.276 | AC8: 0 | AD8: 1259.3185 | AE8: 34806.097 | AF8: 61107.196
A9: 5 | B9: Wholesale & Retail Trade | C9: Wholesale Trade | D9: 68.871 | E9: 14054.25 | F9: 165.5831 | G9: 1990.2075 | H9: 4805.4783 | I9: 366.7311 | J9: 5843.1712 | K9: 138.7063 | L9: 687.6269 | M9: 5665.486 | N9: 1076.0765 | O9: 442.0828 | P9: 34.6188 | Q9: 1120.9424 | R9: 467.4693 | S9: 1518.6727 | T9: 265.4476 | U9: 642.9962 | V9: 110.6991 | W9: 211.2716 | X9: 39676.389 | Z9: 7457.1688 | AA9: 86.3626 | AB9: 5450.2849 | AC9: -0.7815 | AD9: 196888.85 | AE9: 209881.89 | AF9: 249558.28
A10: 6 | B10: Wholesale & Retail Trade | C10: Retail Trade | D10: 0.2515 | E10: 70.4416 | F10: 4.5977 | G10: 214.3577 | H10: 524.2712 | I10: 230.3392 | J10: 228.005 | K10: 5.1914 | L10: 153.0098 | M10: 222.9619 | N10: 78.1325 | O10: 48.2787 | P10: 3.4966 | Q10: 108.2861 | R10: 35.2576 | S10: 150.0523 | T10: 28.7063 | U10: 67.756 | V10: 13.931 | W10: 27.3088 | X10: 2214.6328 | Z10: 11656.371 | AA10: 10.6665 | AB10: 140.4975 | AC10: 0 | AD10: 1242.1405 | AE10: 13049.675 | AF10: 15264.308
A11: 7 | B11: Transportation & Storage | C11: Transportation & Storage | D11: 9.7619 | E11: 2521.8041 | F11: 109.8131 | G11: 236.7421 | H11: 24658.315 | I11: 666.437 | J11: 79642.327 | K11: 23.1531 | L11: 91.9332 | M11: 1620.908 | N11: 823.4893 | O11: 403.981 | P11: 34.5172 | Q11: 445.2801 | R11: 494.7555 | S11: 2706.3841 | T11: 91.3204 | U11: 142.6469 | V11: 63.333 | W11: 53.7776 | X11: 114840.68 | Z11: 6002.1411 | AA11: 46.4959 | AB11: 232.0372 | AC11: -0.302 | AD11: 138946.03 | AE11: 145226.4 | AF11: 260067.08
A12: 8 | B12: Accommodation & Food Services | C12: Accommodation | D12: 0.0964 | E12: 53.7392 | F12: 9.8355 | G12: 61.3597 | H12: 141.3523 | I12: 64.0218 | J12: 437.5832 | K12: 3.6412 | L12: 23.5359 | M12: 104.8144 | N12: 158.6432 | O12: 21.0473 | P12: 0.1812 | Q12: 123.3064 | R12: 50.0269 | S12: 81.0936 | T12: 17.7247 | U12: 14.4858 | V12: 14.9424 | W12: 17.3528 | X12: 1398.7838 | Z12: 2098.3746 | AA12: 109.195 | AB12: 48.5862 | AC12: 0 | AD12: 681.0768 | AE12: 2937.2326 | AF12: 4336.0165
A13: 9 | B13: Accommodation & Food Services | C13: Food & Beverage Services | D13: 1.1318 | E13: 74.686 | F13: 16.7224 | G13: 59.1297 | H13: 489.1515 | I13: 72.8334 | J13: 768.7048 | K13: 7.0638 | L13: 73.2845 | M13: 215.9257 | N13: 714.5129 | O13: 50.8268 | P13: 0.5425 | Q13: 155.8814 | R13: 70.9334 | S13: 95.8801 | T13: 33.2543 | U13: 39.7105 | V13: 30.6616 | W13: 22.5965 | X13: 2993.4337 | Z13: 8884.7111 | AA13: 5.4982 | AB13: 46.3927 | AC13: 0 | AD13: 847.1809 | AE13: 9783.783 | AF13: 12777.217
A14: 10 | B14: Information & Communications | C14: Information & Communications | D14: 4.6582 | E14: 1667.5938 | F14: 236.125 | G14: 282.3433 | H14: 5098.2262 | I14: 422.8942 | J14: 2065.1096 | K14: 94.9026 | L14: 149.2372 | M14: 35361.026 | N14: 5734.1584 | O14: 995.1886 | P14: 47.7574 | Q14: 3413.617 | R14: 582.912 | S14: 2569.8275 | T14: 604.1854 | U14: 881.4769 | V14: 313.3162 | W14: 193.9254 | X14: 60718.481 | Z14: 4987.1013 | AA14: 284.9416 | AB14: 6392.4461 | AC14: -0.0197 | AD14: 84878.845 | AE14: 96543.314 | AF14: 157261.8
A15: 11 | B15: Financial & Insurance Services | C15: Finance & Insurance | D15: 4.9185 | E15: 2099.9051 | F15: 312.4429 | G15: 508.5516 | H15: 9129.2848 | I15: 713.735 | J15: 2198.3664 | K15: 179.0606 | L15: 206.8769 | M15: 2548.5654 | N15: 25704.34 | O15: 3760.374 | P15: 2280.6058 | Q15: 1635.5499 | R15: 719.3892 | S15: 5293.0698 | T15: 226.0806 | U15: 362.6437 | V15: 178.9246 | W15: 139.6902 | X15: 58202.374 | Z15: 23323.649 | AA15: 583.4589 | AB15: 841.5357 | AC15: 0 | AD15: 70480.245 | AE15: 95228.888 | AF15: 153431.26
A16: 12 | B16: Real Estate Services | C16: Real estate | D16: 0.9835 | E16: 1067.7104 | F16: 171.1844 | G16: 251.0616 | H16: 3880.9663 | I16: 2466.3354 | J16: 1205.8458 | K16: 251.4535 | L16: 1157.8298 | M16: 1832.0038 | N16: 2063.9159 | O16: 2042.6171 | P16: 5.6398 | Q16: 1504.6507 | R16: 525.3713 | S16: 690.329 | T16: 431.7099 | U16: 751.7993 | V16: 413.557 | W16: 480.6028 | X16: 21195.567 | Z16: 2495.3738 | AA16: 47.783 | AB16: 8796.7465 | AC16: -0.0001 | AD16: 902.885 | AE16: 12242.788 | AF16: 33438.355
... A24: 20 | B24: Other Community, Social & Personal Services | C24: Other Services – Others | D24: 0.9978 | E24: 92.4883 | F24: 31.3221 | G24: 70.1822 | H24: 177.5884 | I24: 63.0819 | J24: 370.1575 | K24: 32.6719 | L24: 16.0899 | M24: 273.9497 | N24: 185.138 | O24: 57.3611 | P24: 53.5599 | Q24: 132.506 | R24: 71.2003 | S24: 527.0691 | T24: 121.9666 | U24: 131.3745 | V24: 89.0104 | W24: 94.5301 | X24: 2592.2458 | Z24: 6072.0865 | AA24: 63.5923 | AB24: 50.3783 | AC24: 0 | AD24: 282.8262 | AE24: 6468.8833 | AF24: 9061.1292
A25: RT1 | C25: Total domestic use at basic prices | D25: 304.8402 | E25: 100750.61 | F25: 5626.8191 | G25: 32640.585 | H25: 65840.336 | I25: 6981.8559 | J25: 112927.48 | K25: 1619.8525 | L25: 5335.6553 | M25: 62000.298 | N25: 43291.121 | O25: 15572.488 | P25: 4304.5999 | Q25: 19554.146 | R25: 7275.7743 | S25: 21138.181 | T25: 4220.2224 | U25: 8546.934 | V25: 2921.362 | W25: 2266.3087 | X25: 523119.47 | Z25: 128734.7 | AA25: 61847.753 | AB25: 72920.074 | AC25: -388.3131 | AD25: 820978.16 | AE25: 1084092.4 | AF25: 1607211.8
A26: 21 | C26: Imports of goods and services | D26: 301.3626 | E26: 198664.11 | F26: 6289.7383 | G26: 11438.824 | H26: 76984.555 | I26: 1094.2933 | J26: 93938.285 | K26: 496.968 | L26: 2840.2682 | M26: 64506.33 | N26: 34345.269 | O26: 964.095 | P26: 0 | Q26: 16716.892 | R26: 2859.1561 | S26: 8726.8974 | T26: 1427.9778 | U26: 2813.5143 | V26: 487.1224 | W26: 983.479 | X26: 525879.14 | Z26: 25176.557 | AA26: 0 | AB26: 47210.109 | AC26: 10427.513 | AD26: 263073.09 | AE26: 345887.27 | AF26: 871766.41
